<?xml version="1.0"?>
<robot xmlns:xacro="http://wiki.ros.org/xacro">
    <xacro:macro name="kuka_iiwa_14" params="prefix">


        <xacro:property name="PI" value="3.14"/>

        <!-- ********************* LINKS *********************** -->

        <link name="world"/>

        <joint name="world_joint" type="fixed">
            <parent link="world"/>
            <child link="base_link"/>
            <origin xyz="0.0 0.0 0.0" rpy="0.0 0.0 0.0"/>
        </joint>

        <link name="${prefix}base_link">
            <inertial>
                <origin xyz="-0.1 0 0.07" rpy="0 0 0"/>
                <mass value="5"/>
                <inertia ixx="0.05" ixy="0" ixz="0" iyy="0.06" iyz="0" izz="0.03"/>
            </inertial>

            <visual>
                <origin xyz="0 0 0" rpy="0 0 0"/>
                <geometry>
                    <mesh filename="package://kuka_iiwa_14_support/meshes/visual/link_0.dae"/>
                </geometry>
            </visual>

            <collision>
                <origin xyz="0 0 0" rpy="0 0 0"/>
                <geometry>
                    <mesh filename="package://kuka_iiwa_14_support/meshes/collision/link_0.stl"/>
                </geometry>
            </collision>

            <self_collision_checking>
                <origin xyz="0 0 0" rpy="0 0 0"/>
                <geometry>
                    <capsule radius="0.15" length="0.25"/>
                </geometry>
            </self_collision_checking>
        </link>
        <link name="${prefix}link_1">
            <inertial>
                <origin xyz="0 -0.03 0.12" rpy="0 0 0"/>
                <mass value="4"/>
                <inertia ixx="0.1" ixy="0" ixz="0" iyy="0.09" iyz="0" izz="0.02"/>
            </inertial>

            <visual>
                <origin xyz="0 0 0" rpy="0 0 0"/>
                <geometry>
                    <mesh filename="package://kuka_iiwa_14_support/meshes/visual/link_1.dae"/>
                </geometry>
            </visual>

            <collision>
                <origin xyz="0 0 0" rpy="0 0 0"/>
                <geometry>
                    <mesh filename="package://kuka_iiwa_14_support/meshes/collision/link_1.stl"/>
                </geometry>
            </collision>
        </link>
        <link name="${prefix}link_2">
            <inertial>
                <origin xyz="0.0003 0.059 0.042" rpy="0 0 0"/>
                <mass value="4"/>
                <inertia ixx="0.05" ixy="0" ixz="0" iyy="0.018" iyz="0" izz="0.044"/>
            </inertial>

            <visual>
                <origin xyz="0 0 0" rpy="0 0 0"/>
                <geometry>
                    <mesh filename="package://kuka_iiwa_14_support/meshes/visual/link_2.dae"/>
                </geometry>
            </visual>

            <collision>
                <origin xyz="0 0 0" rpy="0 0 0"/>
                <geometry>
                    <mesh filename="package://kuka_iiwa_14_support/meshes/collision/link_2.stl"/>
                </geometry>
            </collision>
        </link>
        <link name="${prefix}link_3">
            <inertial>
                <origin xyz="0 0.03 0.13" rpy="0 0 0"/>
                <mass value="3"/>
                <inertia ixx="0.08" ixy="0" ixz="0" iyy="0.075" iyz="0" izz="0.01"/>
            </inertial>

            <visual>
                <origin xyz="0 0 0" rpy="0 0 0"/>
                <geometry>
                    <mesh filename="package://kuka_iiwa_14_support/meshes/visual/link_3.dae"/>
                </geometry>
            </visual>

            <collision>
                <origin xyz="0 0 0" rpy="0 0 0"/>
                <geometry>
                    <mesh filename="package://kuka_iiwa_14_support/meshes/collision/link_3.stl"/>
                </geometry>
            </collision>
        </link>
        <link name="${prefix}link_4">
            <inertial>
                <origin xyz="0 0.067 0.034" rpy="0 0 0"/>
                <mass value="2.7"/>
                <inertia ixx="0.03" ixy="0" ixz="0" iyy="0.01" iyz="0" izz="0.029"/>
            </inertial>

            <visual>
                <origin xyz="0 0 0" rpy="0 0 0"/>
                <geometry>
                    <mesh filename="package://kuka_iiwa_14_support/meshes/visual/link_4.dae"/>
                </geometry>
            </visual>

            <collision>
                <origin xyz="0 0 0" rpy="0 0 0"/>
                <geometry>
                    <mesh filename="package://kuka_iiwa_14_support/meshes/collision/link_4.stl"/>
                </geometry>
            </collision>
        </link>
        <link name="${prefix}link_5">
            <inertial>
                <origin xyz="0.0001 0.021 0.076" rpy="0 0 0"/>
                <mass value="1.7"/>
                <inertia ixx="0.02" ixy="0" ixz="0" iyy="0.018" iyz="0" izz="0.005"/>
            </inertial>

            <visual>
                <origin xyz="0 0 0" rpy="0 0 0"/>
                <geometry>
                    <mesh filename="package://kuka_iiwa_14_support/meshes/visual/link_5.dae"/>
                </geometry>
            </visual>

            <collision>
                <origin xyz="0 0 0" rpy="0 0 0"/>
                <geometry>
                    <mesh filename="package://kuka_iiwa_14_support/meshes/collision/link_5.stl"/>
                </geometry>
            </collision>
        </link>
        <link name="${prefix}link_6">
            <inertial>
                <origin xyz="0 0.0006 0.0004" rpy="0 0 0"/>
                <mass value="1.8"/>
                <inertia ixx="0.025" ixy="0" ixz="0" iyy="0.0136" iyz="0" izz="0.0247"/>
            </inertial>

            <visual>
                <origin xyz="0 0 0" rpy="0 0 0"/>
                <geometry>
                    <mesh filename="package://kuka_iiwa_14_support/meshes/visual/link_6.dae"/>
                </geometry>
            </visual>

            <collision>
                <origin xyz="0 0 0" rpy="0 0 0"/>
                <geometry>
                    <mesh filename="package://kuka_iiwa_14_support/meshes/collision/link_6.stl"/>
                </geometry>
            </collision>
        </link>

        <link name="${prefix}link_7">
            <inertial>
                <origin xyz="0 0 0.02" rpy="0 0 0"/>
                <mass value="${0.3 / 0.308 * 0.44}"/>
                <inertia ixx="0.01" ixy="0" ixz="0" iyy="0.01" iyz="0" izz="0.01"/>
            </inertial>

            <visual>
                <origin xyz="0 0 0" rpy="0 0 0"/>
                <geometry>
                    <mesh filename="package://kuka_iiwa_14_support/meshes/visual/link_7.dae"/>
                </geometry>
            </visual>

            <collision>
                <origin xyz="0 0 0" rpy="0 0 0"/>
                <geometry>
                    <mesh filename="package://kuka_iiwa_14_support/meshes/collision/link_7.stl"/>
                </geometry>
            </collision>
        </link>


        <!-- This frame corresponds to the $FLANGE coordinate system in controllers -->
        <link name="${prefix}tool0"/>

        <!-- ********************* JOINTS *********************** -->

        <joint name="${prefix}joint_1" type="revolute">
            <parent link="${prefix}base_link"/>
            <child link="${prefix}link_1"/>
            <origin xyz="0 0 0.1575" rpy="0 0 0"/>
            <axis xyz="0 0 1"/>
            <limit lower="${-170 * PI / 180}" upper="${170 * PI / 180}"
                   effort="300" velocity="10"/>
            <dynamics damping="0.1" friction="0.1"/>
        </joint>

        <joint name="${prefix}joint_2" type="revolute">
            <parent link="${prefix}link_1"/>
            <child link="${prefix}link_2"/>
            <origin xyz="0 0 0.2025" rpy="${PI / 2}   0 ${PI}"/>
            <axis xyz="0 0 1"/>
            <limit lower="${-120 * PI / 180}" upper="${120 * PI / 180}"
                          effort="300" velocity="10"/>
            <dynamics damping="0.1" friction="0.1"/>
        </joint>

        <joint name="${prefix}joint_3" type="revolute">
            <parent link="${prefix}link_2"/>
            <child link="${prefix}link_3"/>
            <origin xyz="0 0.2045 0" rpy="${PI / 2} 0 ${PI}"/>
            <axis xyz="0 0 1"/>
            <limit lower="${-170 * PI / 180}" upper="${170 * PI / 180}"
                           effort="300" velocity="10"/>
            <dynamics damping="0.1" friction="0.1"/>
        </joint>

        <joint name="${prefix}joint_4" type="revolute">
            <parent link="${prefix}link_3"/>
            <child link="${prefix}link_4"/>
            <origin xyz="0 0 0.2155" rpy="${PI / 2} 0 0"/>
            <axis xyz="0 0 1"/>
            <limit lower="${-120 * PI / 180}" upper="${120 * PI / 180}"
                          effort="300" velocity="10"/>
            <dynamics damping="0.1" friction="0.1"/>
        </joint>

        <joint name="${prefix}joint_5" type="revolute">
            <parent link="${prefix}link_4"/>
            <child link="${prefix}link_5"/>
            <origin xyz="0 0.1845 0" rpy="${-PI / 2} ${PI} 0"/>
            <axis xyz="0 0 1"/>
            <limit lower="${-170 * PI / 180}" upper="${170 * PI / 180}"
                          effort="300" velocity="10"/>
            <dynamics damping="0.1" friction="0.1"/>
        </joint>

        <joint name="${prefix}joint_6" type="revolute">
            <parent link="${prefix}link_5"/>
            <child link="${prefix}link_6"/>
            <origin xyz="0 0 0.2155" rpy="${PI / 2} 0 0"/>
            <axis xyz="0 0 1"/>
            <limit lower="${-120 * PI / 180}" upper="${120 * PI / 180}"
                      effort="300" velocity="10"/>
            <dynamics damping="0.1" friction="0.1"/>
        </joint>

        <joint name="${prefix}joint_7" type="revolute">
            <parent link="${prefix}link_6"/>
            <child link="${prefix}link_7"/>
            <origin xyz="0 0.081 0" rpy="${- PI / 2} ${PI} 0"/>
            <axis xyz="0 0 1"/>
            <limit lower="${-175 * PI / 180}" upper="${175 * PI / 180}"
                           effort="300" velocity="10"/>
            <dynamics damping="0.1" friction="0.1"/>
        </joint>

        <joint name="${prefix}joint_7-tool0" type="fixed">
            <parent link="${prefix}link_7"/>
            <child link="${prefix}tool0"/>
            <origin xyz="0 0 0" rpy="0 0.000000 0"/>
        </joint>

    </xacro:macro>
</robot>


