<?xml version="1.0"  encoding="UTF-8"?>
<robot xmlns:xacro="http://wiki.ros.org/xacro">

    <!-- PI константа -->
    <xacro:property name="PI" value="3.1415926535897931"/>

    <!--т.к. колёса у нас одинаоквые, а их 4 для экономии места запишем их параметры через переменные-->
    <xacro:property name="caster_offset_x" value="0.228"/>
    <xacro:property name="caster_offset_y" value="0.158"/>
    <xacro:property name="caster_offset_z" value="-0.034"/>
    <xacro:property name="wheel_offset_x" value="0.0"/>
    <xacro:property name="wheel_offset_y" value="0.0"/>
    <xacro:property name="wheel_offset_z" value="0.0"/>
    <xacro:property name="wheel_radius" value="0.05"/>
    <xacro:property name="wheel_length" value="0.005"/>
    <xacro:property name="caster_joint_damping" value="1.0"/>
    <xacro:property name="caster_joint_friction" value="1.0"/>
    <xacro:property name="caster_joint_effort" value="30"/>
    <xacro:property name="caster_joint_velocity" value="10"/>
    <xacro:property name="wheel_joint_damping" value="1.0"/>
    <xacro:property name="wheel_joint_friction" value="1.0"/>
    <xacro:property name="wheel_joint_effort" value="30"/>
    <xacro:property name="wheel_joint_velocity" value="10"/>
    <xacro:macro name="wheel_link_content">
        <inertial>
            <mass value="0.4"/>
            <origin xyz="0 0 0"/>
            <inertia ixx="0.012411765597" ixy="-0.000711733678" ixz="0.00050272983" iyy="0.015218160428"
                     iyz="-0.000004273467" izz="0.011763977943"/>
        </inertial>
        <visual>
            <origin xyz="0 0 0" rpy="0 0 0"/>
            <geometry>
                <sphere radius="${wheel_radius}"/>
            </geometry>
        </visual>
        <collision>
            <origin xyz="0 0 0" rpy="${PI/2} 0 0"/>
            <geometry>
                <cylinder radius="${wheel_radius}" length="${wheel_radius}"/>
            </geometry>
        </collision>
    </xacro:macro>
    <xacro:macro name="caster_link_content">
        <inertial>
            <mass value="0.1"/>
            <origin xyz="0 0 0"/>
            <inertia ixx="0.012411765597" ixy="-0.000711733678" ixz="0.00050272983" iyy="0.015218160428"
                     iyz="-0.000004273467" izz="0.011763977943"/>
        </inertial>
    </xacro:macro>

    <xacro:macro name="kuka_youbot" params="prefix main_frame_name">

        <!--******************************************BASE*************************************************-->
        <link name="${prefix}${main_frame_name}">
            <visual>
                <origin xyz="0 0 0" rpy="0 0 0"/>
                <geometry>
                    <box size="0.001 0.001 0.001"/>
                </geometry>
            </visual>
            <collision>
                <origin xyz="0 0 -0.050" rpy="0 0 0"/>
                <geometry>
                    <box size="0.001 0.001 0.001"/>
                </geometry>
            </collision>
        </link>
        <link name="${prefix}plate_link">
            <inertial>
                <origin xyz="0 0 0" rpy="0 0 0"/>
                <mass value="1"/>
                <inertia ixx="0.01" ixy="0" ixz="0" iyy="0.01" iyz="0" izz="0.01"/>
            </inertial>
            <visual>
                <origin xyz="0 0 0" rpy="0 0 0"/>
                <geometry>
                    <mesh filename="package://kuka_youbot_support/meshes/visual/plate.dae"/>
                </geometry>
            </visual>
            <collision>
                <origin xyz="0 0 0" rpy="0 0 0"/>
                <geometry>
                    <mesh filename="package://kuka_youbot_support/meshes/collision/plate.stl"/>
                </geometry>
            </collision>
        </link>
        <link name="${prefix}base_link">
            <inertial>
                <mass value="100"/>
                <origin xyz="0 0 0"/>
                <inertia ixx="5.652232699207" ixy="-0.009719934438" ixz="1.293988226423" iyy="5.669473158652"
                         iyz="-0.007379583694" izz="3.683196351726"/>
            </inertial>
            <visual>
                <origin xyz="0 0 0" rpy="0 0 0"/>
                <geometry>
                    <mesh filename="package://kuka_youbot_support/meshes/visual/base.dae"/>
                </geometry>
            </visual>
            <collision>
                <origin xyz="0 0 0" rpy="0 0 0"/>
                <geometry>
                    <mesh filename="package://kuka_youbot_support/meshes/collision/base.stl"/>
                </geometry>
            </collision>
        </link>
        <link name="caster_link_fl">
            <xacro:caster_link_content/>
        </link>
        <link name="wheel_link_fl">
            <xacro:wheel_link_content/>
        </link>
        <link name="caster_link_fr">
            <xacro:caster_link_content/>
        </link>
        <link name="wheel_link_fr">
            <xacro:wheel_link_content/>
        </link>
        <link name="caster_link_bl">
            <xacro:caster_link_content/>
        </link>
        <link name="wheel_link_bl">
            <xacro:wheel_link_content/>
        </link>
        <link name="caster_link_br">
            <xacro:caster_link_content/>
        </link>
        <link name="wheel_link_br">
            <xacro:wheel_link_content/>
        </link>

        <joint name="${prefix}plate_joint" type="fixed">
            <origin xyz="-0.159 0 0.046" rpy="0 0 0"/>
            <parent link="${prefix}base_link"/>
            <child link="${prefix}plate_link"/>
        </joint>
        <joint name="${prefix}footprint_joint" type="fixed">
            <origin xyz="0 0 0" rpy="0 0 0"/>
            <child link="${prefix}base_link"/>
            <parent link="${prefix}${main_frame_name}"/>
        </joint>
        <joint name="caster_joint_fl" type="continuous">
            <origin xyz="${caster_offset_x} ${caster_offset_y} ${caster_offset_z}" rpy="0 0 0"/>
            <axis xyz="0 0 1"/>
            <limit effort="${caster_joint_effort}" velocity="${caster_joint_velocity}"/>
            <dynamics damping="${caster_joint_damping}" friction="${caster_joint_friction}"/>
            <parent link="${prefix}base_link"/>
            <child link="caster_link_fl"/>
        </joint>
        <joint name="wheel_joint_fl" type="continuous">
            <axis xyz="0 1 0"/>
            <limit effort="${wheel_joint_effort}" velocity="${wheel_joint_velocity}"/>
            <origin xyz="${wheel_offset_x} ${wheel_offset_y} ${wheel_offset_z}" rpy="0 0 0"/>
            <parent link="caster_link_fl"/>
            <dynamics damping="${wheel_joint_damping}" friction="${wheel_joint_friction}"/>
            <child link="wheel_link_fl"/>
        </joint>
        <joint name="caster_joint_fr" type="continuous">
            <origin xyz="${caster_offset_x} ${-caster_offset_y} ${caster_offset_z}" rpy="0 0 0"/>
            <axis xyz="0 0 1"/>
            <limit effort="${caster_joint_effort}" velocity="${caster_joint_velocity}"/>
            <dynamics damping="${caster_joint_damping}" friction="${caster_joint_friction}"/>
            <parent link="${prefix}base_link"/>
            <child link="caster_link_fr"/>
        </joint>
        <joint name="wheel_joint_fr" type="continuous">
            <axis xyz="0 1 0"/>
            <limit effort="${wheel_joint_effort}" velocity="${wheel_joint_velocity}"/>
            <dynamics damping="${wheel_joint_damping}" friction="${wheel_joint_friction}"/>
            <origin xyz="${wheel_offset_x} ${wheel_offset_y} ${wheel_offset_z}" rpy="0 0 0"/>
            <parent link="caster_link_fr"/>
            <child link="wheel_link_fr"/>
        </joint>
        <joint name="caster_joint_bl" type="continuous">
            <origin xyz="${-caster_offset_x} ${caster_offset_y} ${caster_offset_z}" rpy="0 0 0"/>
            <axis xyz="0 0 1"/>
            <limit effort="${caster_joint_effort}" velocity="${caster_joint_velocity}"/>
            <dynamics damping="${caster_joint_damping}" friction="${caster_joint_friction}"/>
            <parent link="${prefix}base_link"/>
            <child link="caster_link_bl"/>
        </joint>
        <joint name="wheel_joint_bl" type="continuous">
            <axis xyz="0 1 0"/>
            <limit effort="10" velocity="10"/>
            <limit effort="${wheel_joint_effort}" velocity="${wheel_joint_velocity}"/>
            <dynamics damping="${wheel_joint_damping}" friction="${wheel_joint_friction}"/>
            <origin xyz="${wheel_offset_x} ${wheel_offset_y} ${wheel_offset_z}" rpy="0 0 0"/>
            <parent link="caster_link_bl"/>
            <child link="wheel_link_bl"/>
        </joint>
        <joint name="caster_joint_br" type="continuous">
            <origin xyz="${-caster_offset_x} ${-caster_offset_y} ${caster_offset_z}" rpy="0 0 0"/>
            <axis xyz="0 0 1"/>
            <limit effort="${caster_joint_effort}" velocity="${caster_joint_velocity}"/>
            <dynamics damping="${caster_joint_damping}" friction="${caster_joint_friction}"/>
            <parent link="${prefix}base_link"/>
            <child link="caster_link_br"/>
        </joint>
        <joint name="wheel_joint_br" type="continuous">
            <axis xyz="0 1 0"/>
            <limit effort="${wheel_joint_effort}" velocity="${wheel_joint_velocity}"/>
            <dynamics damping="${wheel_joint_damping}" friction="${wheel_joint_friction}"/>
            <origin xyz="${wheel_offset_x} ${wheel_offset_y} ${wheel_offset_z}" rpy="0 0 0"/>
            <parent link="caster_link_br"/>
            <child link="wheel_link_br"/>
        </joint>

        <!--**************************ARM************************************-->
        <link name="${prefix}arm_link_0">
            <inertial>
                <origin xyz="0 0 0" rpy="0 0 0"/>
                <mass value="0.845"/>
                <inertia ixx="0.01" ixy="0" ixz="0" iyy="0.01" iyz="0" izz="0.01"/>
            </inertial>
            <visual>
                <origin xyz="0 0 0" rpy="0 0 0"/>
                <geometry>
                    <mesh filename="package://kuka_youbot_support/meshes/visual/link_0.dae"/>
                </geometry>
            </visual>
            <collision>
                <origin xyz="0 0 0" rpy="0 0 0"/>
                <geometry>
                    <mesh filename="package://kuka_youbot_support/meshes/collision/link_0.stl"/>
                </geometry>
            </collision>
        </link>
        <link name="${prefix}arm_link_1">
            <inertial>
                <mass value="2.412"/>
                <origin xyz="0.01489 0.00213 0.00213" rpy="0 0 0"/>
                <inertia ixx="0.003863" ixy="-0.000979" ixz="0.000000" iyy="0.006196" iyz="0.000000" izz="0.006369"/>
            </inertial>
            <visual>
                <origin xyz="0 0 0" rpy="0 0 0"/>
                <geometry>
                    <mesh filename="package://kuka_youbot_support/meshes/visual/link_1.dae"/>
                </geometry>
            </visual>
            <collision>
                <origin xyz="0 0 0" rpy="0 0 0"/>
                <geometry>
                    <mesh filename="package://kuka_youbot_support/meshes/collision/link_1.stl"/>
                </geometry>
            </collision>
        </link>
        <link name="${prefix}arm_link_2">
            <inertial>
                <mass value="1.155"/>
                <origin xyz="0.10453 0.0017 -0.00297"
                        rpy="0 0 0"/>
                <inertia ixx="0.000823" ixy="0.000000" ixz="-0.000000" iyy="0.004447" iyz="0.000000" izz="0.004439"/>
            </inertial>
            <visual>
                <origin xyz="0 -0.032 0.078" rpy="0 0 0"/>
                <geometry>
                    <mesh filename="package://kuka_youbot_support/meshes/visual/link_2.dae"/>
                </geometry>
            </visual>
            <collision>
                <origin xyz="0 -0.032 0.078" rpy="0 0 0"/>
                <geometry>
                    <mesh filename="package://kuka_youbot_support/meshes/collision/link_2.stl"/>
                </geometry>
            </collision>
        </link>
        <link name="${prefix}arm_link_3">
            <inertial>
                <mass value="0.934"/>
                <origin xyz="0.0001 0.0967 0.02107"
                        rpy="0 0 0"/>
                <inertia ixx="0.002459" ixy="0.000000" ixz="0.000000" iyy="0.002571" iyz="-0.000000" izz="0.000535"/>
            </inertial>
            <visual>
                <origin xyz="0.000 0.028 0.079" rpy="0 0 0"/>
                <geometry>
                    <mesh filename="package://kuka_youbot_support/meshes/visual/link_3.dae"/>
                </geometry>
            </visual>
            <collision>
                <origin xyz="0.000 0.028 0.079" rpy="0 0 0"/>
                <geometry>
                    <mesh filename="package://kuka_youbot_support/meshes/collision/link_3.stl"/>
                </geometry>
            </collision>
        </link>
        <link name="${prefix}arm_link_4">
            <inertial>
                <mass value="0.877"/>
                <origin xyz="0.00011 0.05103 -0.02319"
                        rpy="0 0 0"/>
                <inertia ixx="0.000869" ixy="0.000000" ixz="-0.000000" iyy="0.001173" iyz="-0.000231" izz="0.001091"/>
            </inertial>
            <visual>
                <origin xyz="0 -0.010 0.029" rpy="0 0 0"/>
                <geometry>
                    <mesh filename="package://kuka_youbot_support/meshes/visual/link_4.dae"/>
                </geometry>
            </visual>
            <collision>
                <origin xyz="0 -0.010 0.029" rpy="0 0 0"/>
                <geometry>
                    <mesh filename="package://kuka_youbot_support/meshes/collision/link_4.stl"/>
                </geometry>
            </collision>
        </link>
        <link name="${prefix}arm_link_5">
            <inertial>
                <mass value="0.251"/>
                <origin xyz="0 0.00115 -0.01683"
                        rpy="0 0 0"/>
                <inertia ixx="0.000280" ixy="0.000000" ixz="0.000000" iyy="0.000339" iyz="0.000000" izz="0.000119"/>
            </inertial>
            <visual>
                <origin xyz="0.003 0 -0.034" rpy="0 0 0"/>
                <geometry>
                    <mesh filename="package://kuka_youbot_support/meshes/visual/link_5.dae"/>
                </geometry>
            </visual>

            <collision>
                <origin xyz="0.003 0 -0.034" rpy="0 0 0"/>
                <geometry>
                    <mesh filename="package://kuka_youbot_support/meshes/collision/link_5.stl"/>
                </geometry>
            </collision>
        </link>

        <joint name="${prefix}arm_joint_0" type="fixed">
            <origin xyz="0.143 0 0.046" rpy="0 0 0"/>
            <parent link="${prefix}base_link"/>
            <child link="${prefix}arm_link_0"/>
        </joint>
        <joint name="${prefix}arm_joint_1" type="revolute">
            <origin xyz="0.024 0 0.096" rpy="0 0 ${170 * PI / 180}"/>
            <parent link="${prefix}arm_link_0"/>
            <child link="${prefix}arm_link_1"/>
            <axis xyz="0 0 -1"/>
            <dynamics damping="1" friction="1"/>
            <limit effort="${9.5}" velocity="${PI / 2.0}" lower="0" upper="${PI * (169 + 169) / 180}"/>
        </joint>
        <joint name="${prefix}arm_joint_2" type="revolute">
            <origin xyz="0.033 0 0.019" rpy="0 ${-65 * PI / 180} 0"/>
            <parent link="${prefix}arm_link_1"/>
            <child link="${prefix}arm_link_2"/>
            <axis xyz="0 1 0"/>
            <dynamics damping="1" friction="1"/>
            <limit effort="${9.5}" velocity="${PI / 2.0}" lower="0" upper="${PI * (90 + 65) / 180}"/>
        </joint>
        <joint name="${prefix}arm_joint_3" type="revolute">
            <origin xyz="0.000 0.000 0.155" rpy="0 ${146 * PI / 180} 0"/>
            <parent link="${prefix}arm_link_2"/>
            <child link="${prefix}arm_link_3"/>
            <axis xyz="0 1 0"/>
            <dynamics damping="1" friction="1"/>
            <limit effort="${6}" velocity="${PI / 2.0}" lower="-${PI * (146 + 151) / 180}" upper="0"/>
        </joint>
        <joint name="${prefix}arm_joint_4" type="revolute">
            <origin xyz="0.000 0.000 0.135" rpy="0 ${-102.5 * PI / 180} 0"/>
            <parent link="${prefix}arm_link_3"/>
            <child link="${prefix}arm_link_4"/>
            <axis xyz="0 1 0"/>
            <dynamics damping="1" friction="1"/>
            <limit effort="${2}" velocity="${PI / 2.0}" lower="0" upper="${PI * (102.5 + 102.5) / 180}"/>
        </joint>
        <joint name="${prefix}arm_joint_5" type="revolute">
            <origin xyz="-0.002 0 0.130" rpy="0 0 ${167.5 * PI / 180}"/>
            <parent link="${prefix}arm_link_4"/>
            <child link="${prefix}arm_link_5"/>
            <axis xyz="0 0 -1"/>
            <dynamics damping="1" friction="1"/>
            <limit effort="1" velocity="${PI / 2.0}" lower="0" upper="${PI * (167.5 + 167.5) / 180}"/>
        </joint>

        <!--*************************GRIPPER*********************-->
        <link name="${prefix}gripper_finger_link_l">
            <inertial>
                <origin xyz="0 -0.001 0" rpy="0 0 0"/>
                <mass value="0.01"/>
                <inertia ixx="0.01" ixy="0" ixz="0" iyy="0.01" iyz="0" izz="0.01"/>
            </inertial>
            <visual>
                <origin xyz="0 0 0" rpy="0 0 0"/>
                <geometry>
                    <mesh filename="package://kuka_youbot_support/meshes/visual/finger.dae"/>
                </geometry>
            </visual>
            <collision>
                <origin xyz="0 0 0" rpy="0 0 0"/>
                <geometry>
                    <mesh filename="package://kuka_youbot_support/meshes/collision/finger.stl"/>
                </geometry>
            </collision>
        </link>
        <link name="${prefix}gripper_finger_link_r">
            <inertial>
                <origin xyz="0.000 -0.001 0" rpy="0 0 0"/>
                <mass value="0.01"/>
                <inertia ixx="0.01" ixy="0" ixz="0" iyy="0.01" iyz="0" izz="0.01"/>
            </inertial>
            <visual>
                <origin xyz="0 0 0" rpy="0 0 0"/>
                <geometry>
                    <mesh filename="package://kuka_youbot_support/meshes/visual/finger.dae"/>
                </geometry>
            </visual>
            <collision>
                <origin xyz="0.000 0 0" rpy="0 0 0"/>
                <geometry>
                    <!--<box size="0.014 0.020 0.046"/>-->
                    <mesh filename="package://kuka_youbot_support/meshes/collision/finger.stl"/>
                </geometry>
            </collision>
        </link>
        <link name="${prefix}_palm_link">
            <inertial>
                <origin xyz="0 0 0" rpy="0 0 0"/>
                <mass value="0.1"/>
                <inertia ixx="0.01" ixy="0" ixz="0" iyy="0.01" iyz="0" izz="0.01"/>
            </inertial>
            <visual>
                <origin xyz="0 0 0" rpy="0 0 0"/>
                <geometry>
                    <mesh filename="package://kuka_youbot_support/meshes/visual/palm.dae"/>
                </geometry>
            </visual>
            <collision>
                <origin xyz="0 0 0" rpy="0 0 0"/>
                <geometry>
                    <mesh filename="package://kuka_youbot_support/meshes/collision/palm.stl"/>
                </geometry>
            </collision>
        </link>

        <joint name="${prefix}_palm_joint" type="fixed">
            <origin xyz="0 0 0" rpy="0 0 0"/>
            <parent link="${prefix}arm_link_5"/>
            <child link="${prefix}_palm_link"/>
        </joint>
        <joint name="${prefix}gripper_finger_joint_l" type="prismatic">
            <origin xyz="0.004 0.008 0.046" rpy="0 0 ${PI}"/>
            <parent link="${prefix}_palm_link"/>
            <child link="${prefix}gripper_finger_link_l"/>
            <axis xyz="0 -1 0"/>
            <dynamics damping="1.0" friction="1.0"/>
            <limit effort="1" velocity="0.1" lower="0" upper="0.0115"/>
        </joint>
        <joint name="${prefix}gripper_finger_joint_r" type="prismatic">
            <origin xyz="0.004 -0.008 0.046" rpy="0 0 0"/>
            <parent link="${prefix}_palm_link"/>
            <child link="${prefix}gripper_finger_link_r"/>
            <axis xyz="0 -1 0"/>
            <dynamics damping="1.0" friction="1.0"/>
            <limit effort="1" velocity="0.1" lower="0" upper="0.0115"/>
        </joint>

    </xacro:macro>
</robot>


